Workbook

Sheet Credit Ledger
A1: RICE CREDIT LEDGER — SALES ON CREDIT & OUTSTANDING BALANCES
A2: Source: 'Customer Sales & Loan Ledger' provided by the owner, 29 Aug 2026. Credit transactions only (40 of 42 rows); the 2 cash rows are on the 'Excluded (Cash)' sheet.
A3: HOW TO USE: do not type anything on this sheet — it is all formulas. Record every payment on the 'Payments' sheet (yellow cells) using the Ledger ID from column A. Total Paid, Balance, Status and Last Payment update by themselves.
A5: Ledger ID | B5: Customer Name | C5: Contact Number | D5: Transaction Date | E5: Product Type | F5: Qty (Sacks) | G5: Unit Price (PHP) | H5: Total Amount (PHP) | I5: Total Paid (PHP) | J5: Balance Due (PHP) | K5: Status | L5: Last Payment | M5: Notes
A6: 1 | B6: Lorna | D6: 46181 | E6: Rice (50 kg/sack) | F6: 1 | G6: 2800 | H6: =F6*G6 -> 2800 | I6: =SUMIF(Payments!$B$6:$B$305,$A6,Payments!$D$6:$D$305) -> 0 | J6: =H6-I6 -> 2800 | K6: =IF($H6=0,"",IF(ROUND($J6,2)<0,"OVERPAID",IF(ROUND($J6,2)=0,"PAID",IF($I6>0,"PARTIAL","UNPAID")))) -> UNPAID | L6: =IF(SUMPRODUCT(MAX((Payments!$B$6:$B$305=$A6)*Payments!$A$6:$A$305))=0,"",SUMPRODUCT(MAX((Payments!$B$6:$B$305=$A6)*Payments!$A$6:$A$305)))
A7: 2 | B7: Ate Lenie | D7: 46181 | E7: Rice (50 kg/sack) | F7: 1 | G7: 2800 | H7: =F7*G7 -> 2800 | I7: =SUMIF(Payments!$B$6:$B$305,$A7,Payments!$D$6:$D$305) -> 0 | J7: =H7-I7 -> 2800 | K7: =IF($H7=0,"",IF(ROUND($J7,2)<0,"OVERPAID",IF(ROUND($J7,2)=0,"PAID",IF($I7>0,"PARTIAL","UNPAID")))) -> UNPAID | L7: =IF(SUMPRODUCT(MAX((Payments!$B$6:$B$305=$A7)*Payments!$A$6:$A$305))=0,"",SUMPRODUCT(MAX((Payments!$B$6:$B$305=$A7)*Payments!$A$6:$A$305)))
A8: 3 | B8: Mingo | D8: 46188 | E8: Rice (25 kg/sack) | F8: 2 | G8: 1400 | H8: =F8*G8 -> 2800 | I8: =SUMIF(Payments!$B$6:$B$305,$A8,Payments!$D$6:$D$305) -> 0 | J8: =H8-I8 -> 2800 | K8: =IF($H8=0,"",IF(ROUND($J8,2)<0,"OVERPAID",IF(ROUND($J8,2)=0,"PAID",IF($I8>0,"PARTIAL","UNPAID")))) -> UNPAID | L8: =IF(SUMPRODUCT(MAX((Payments!$B$6:$B$305=$A8)*Payments!$A$6:$A$305))=0,"",SUMPRODUCT(MAX((Payments!$B$6:$B$305=$A8)*Payments!$A$6:$A$305)))
A9: 4 | B9: Julius | D9: 46189 | E9: Rice (25 kg/sack) | F9: 1 | G9: 1400 | H9: =F9*G9 -> 1400 | I9: =SUMIF(Payments!$B$6:$B$305,$A9,Payments!$D$6:$D$305) -> 0 | J9: =H9-I9 -> 1400 | K9: =IF($H9=0,"",IF(ROUND($J9,2)<0,"OVERPAID",IF(ROUND($J9,2)=0,"PAID",IF($I9>0,"PARTIAL","UNPAID")))) -> UNPAID | L9: =IF(SUMPRODUCT(MAX((Payments!$B$6:$B$305=$A9)*Payments!$A$6:$A$305))=0,"",SUMPRODUCT(MAX((Payments!$B$6:$B$305=$A9)*Payments!$A$6:$A$305)))
A10: 5 | B10: Junard | D10: 46189 | E10: Rice (25 kg/sack) | F10: 1 | G10: 1400 | H10: =F10*G10 -> 1400 | I10: =SUMIF(Payments!$B$6:$B$305,$A10,Payments!$D$6:$D$305) -> 0 | J10: =H10-I10 -> 1400 | K10: =IF($H10=0,"",IF(ROUND($J10,2)<0,"OVERPAID",IF(ROUND($J10,2)=0,"PAID",IF($I10>0,"PARTIAL","UNPAID")))) -> UNPAID | L10: =IF(SUMPRODUCT(MAX((Payments!$B$6:$B$305=$A10)*Payments!$A$6:$A$305))=0,"",SUMPRODUCT(MAX((Payments!$B$6:$B$305=$A10)*Payments!$A$6:$A$305)))
A11: 6 | B11: Juaton Crossing | D11: 46191 | E11: Rice (25 kg/sack) | F11: 2 | G11: 1400 | H11: =F11*G11 -> 2800 | I11: =SUMIF(Payments!$B$6:$B$305,$A11,Payments!$D$6:$D$305) -> 0 | J11: =H11-I11 -> 2800 | K11: =IF($H11=0,"",IF(ROUND($J11,2)<0,"OVERPAID",IF(ROUND($J11,2)=0,"PAID",IF($I11>0,"PARTIAL","UNPAID")))) -> UNPAID | L11: =IF(SUMPRODUCT(MAX((Payments!$B$6:$B$305=$A11)*Payments!$A$6:$A$305))=0,"",SUMPRODUCT(MAX((Payments!$B$6:$B$305=$A11)*Payments!$A$6:$A$305)))
A12: 7 | B12: Junjun SM | D12: 46193 | E12: Rice (25 kg/sack) | F12: 1 | G12: 1400 | H12: =F12*G12 -> 1400 | I12: =SUMIF(Payments!$B$6:$B$305,$A12,Payments!$D$6:$D$305) -> 0 | J12: =H12-I12 -> 1400 | K12: =IF($H12=0,"",IF(ROUND($J12,2)<0,"OVERPAID",IF(ROUND($J12,2)=0,"PAID",IF($I12>0,"PARTIAL","UNPAID")))) -> UNPAID | L12: =IF(SUMPRODUCT(MAX((Payments!$B$6:$B$305=$A12)*Payments!$A$6:$A$305))=0,"",SUMPRODUCT(MAX((Payments!$B$6:$B$305=$A12)*Payments!$A$6:$A$305)))
A13: 8 | B13: Tita Susan | D13: 46194 | E13: Rice (25 kg/sack) | F13: 1 | G13: 1400 | H13: =F13*G13 -> 1400 | I13: =SUMIF(Payments!$B$6:$B$305,$A13,Payments!$D$6:$D$305) -> 0 | J13: =H13-I13 -> 1400 | K13: =IF($H13=0,"",IF(ROUND($J13,2)<0,"OVERPAID",IF(ROUND($J13,2)=0,"PAID",IF($I13>0,"PARTIAL","UNPAID")))) -> UNPAID | L13: =IF(SUMPRODUCT(MAX((Payments!$B$6:$B$305=$A13)*Payments!$A$6:$A$305))=0,"",SUMPRODUCT(MAX((Payments!$B$6:$B$305=$A13)*Payments!$A$6:$A$305))) | M13: Highlighted red in the source ledger — meaning to be confirmed.
A14: 9 | B14: Juaton Crossing | D14: 46193 | E14: Rice (50 kg/sack) | F14: 2 | G14: 2800 | H14: =F14*G14 -> 5600 | I14: =SUMIF(Payments!$B$6:$B$305,$A14,Payments!$D$6:$D$305) -> 0 | J14: =H14-I14 -> 5600 | K14: =IF($H14=0,"",IF(ROUND($J14,2)<0,"OVERPAID",IF(ROUND($J14,2)=0,"PAID",IF($I14>0,"PARTIAL","UNPAID")))) -> UNPAID | L14: =IF(SUMPRODUCT(MAX((Payments!$B$6:$B$305=$A14)*Payments!$A$6:$A$305))=0,"",SUMPRODUCT(MAX((Payments!$B$6:$B$305=$A14)*Payments!$A$6:$A$305))) | M14: Highlighted red in the source ledger — meaning to be confirmed.
A15: 10 | B15: Ranny | D15: 46193 | E15: Rice (50 kg/sack) | F15: 1 | G15: 2800 | H15: =F15*G15 -> 2800 | I15: =SUMIF(Payments!$B$6:$B$305,$A15,Payments!$D$6:$D$305) -> 0 | J15: =H15-I15 -> 2800 | K15: =IF($H15=0,"",IF(ROUND($J15,2)<0,"OVERPAID",IF(ROUND($J15,2)=0,"PAID",IF($I15>0,"PARTIAL","UNPAID")))) -> UNPAID | L15: =IF(SUMPRODUCT(MAX((Payments!$B$6:$B$305=$A15)*Payments!$A$6:$A$305))=0,"",SUMPRODUCT(MAX((Payments!$B$6:$B$305=$A15)*Payments!$A$6:$A$305))) | M15: Highlighted red in the source ledger — meaning to be confirmed.
A16: 11 | B16: Romil | D16: 46195 | E16: Rice (25 kg/sack) | F16: 1 | G16: 1400 | H16: =F16*G16 -> 1400 | I16: =SUMIF(Payments!$B$6:$B$305,$A16,Payments!$D$6:$D$305) -> 0 | J16: =H16-I16 -> 1400 | K16: =IF($H16=0,"",IF(ROUND($J16,2)<0,"OVERPAID",IF(ROUND($J16,2)=0,"PAID",IF($I16>0,"PARTIAL","UNPAID")))) -> UNPAID | L16: =IF(SUMPRODUCT(MAX((Payments!$B$6:$B$305=$A16)*Payments!$A$6:$A$305))=0,"",SUMPRODUCT(MAX((Payments!$B$6:$B$305=$A16)*Payments!$A$6:$A$305)))
A17: 12 | B17: Jun2x B | D17: 46195 | E17: Rice (25 kg/sack) | F17: 1 | G17: 1400 | H17: =F17*G17 -> 1400 | I17: =SUMIF(Payments!$B$6:$B$305,$A17,Payments!$D$6:$D$305) -> 0 | J17: =H17-I17 -> 1400 | K17: =IF($H17=0,"",IF(ROUND($J17,2)<0,"OVERPAID",IF(ROUND($J17,2)=0,"PAID",IF($I17>0,"PARTIAL","UNPAID")))) -> UNPAID | L17: =IF(SUMPRODUCT(MAX((Payments!$B$6:$B$305=$A17)*Payments!$A$6:$A$305))=0,"",SUMPRODUCT(MAX((Payments!$B$6:$B$305=$A17)*Payments!$A$6:$A$305)))
A18: 13 | B18: Bryan | D18: 46195 | E18: Rice (25 kg/sack) | F18: 1 | G18: 1400 | H18: =F18*G18 -> 1400 | I18: =SUMIF(Payments!$B$6:$B$305,$A18,Payments!$D$6:$D$305) -> 0 | J18: =H18-I18 -> 1400 | K18: =IF($H18=0,"",IF(ROUND($J18,2)<0,"OVERPAID",IF(ROUND($J18,2)=0,"PAID",IF($I18>0,"PARTIAL","UNPAID")))) -> UNPAID | L18: =IF(SUMPRODUCT(MAX((Payments!$B$6:$B$305=$A18)*Payments!$A$6:$A$305))=0,"",SUMPRODUCT(MAX((Payments!$B$6:$B$305=$A18)*Payments!$A$6:$A$305)))
A19: 14 | B19: JR | D19: 46195 | E19: Rice (25 kg/sack) | F19: 1 | G19: 1400 | H19: =F19*G19 -> 1400 | I19: =SUMIF(Payments!$B$6:$B$305,$A19,Payments!$D$6:$D$305) -> 0 | J19: =H19-I19 -> 1400 | K19: =IF($H19=0,"",IF(ROUND($J19,2)<0,"OVERPAID",IF(ROUND($J19,2)=0,"PAID",IF($I19>0,"PARTIAL","UNPAID")))) -> UNPAID | L19: =IF(SUMPRODUCT(MAX((Payments!$B$6:$B$305=$A19)*Payments!$A$6:$A$305))=0,"",SUMPRODUCT(MAX((Payments!$B$6:$B$305=$A19)*Payments!$A$6:$A$305)))
A20: 15 | B20: Naldo | D20: 46195 | E20: Rice (25 kg/sack) | F20: 1 | G20: 1400 | H20: =F20*G20 -> 1400 | I20: =SUMIF(Payments!$B$6:$B$305,$A20,Payments!$D$6:$D$305) -> 0 | J20: =H20-I20 -> 1400 | K20: =IF($H20=0,"",IF(ROUND($J20,2)<0,"OVERPAID",IF(ROUND($J20,2)=0,"PAID",IF($I20>0,"PARTIAL","UNPAID")))) -> UNPAID | L20: =IF(SUMPRODUCT(MAX((Payments!$B$6:$B$305=$A20)*Payments!$A$6:$A$305))=0,"",SUMPRODUCT(MAX((Payments!$B$6:$B$305=$A20)*Payments!$A$6:$A$305)))
A21: 16 | B21: Leonard | D21: 46201 | E21: Rice (50 kg/sack) | F21: 1 | G21: 2800 | H21: =F21*G21 -> 2800 | I21: =SUMIF(Payments!$B$6:$B$305,$A21,Payments!$D$6:$D$305) -> 0 | J21: =H21-I21 -> 2800 | K21: =IF($H21=0,"",IF(ROUND($J21,2)<0,"OVERPAID",IF(ROUND($J21,2)=0,"PAID",IF($I21>0,"PARTIAL","UNPAID")))) -> UNPAID | L21: =IF(SUMPRODUCT(MAX((Payments!$B$6:$B$305=$A21)*Payments!$A$6:$A$305))=0,"",SUMPRODUCT(MAX((Payments!$B$6:$B$305=$A21)*Payments!$A$6:$A$305))) | M21: Highlighted red in the source ledger — meaning to be confirmed.
A22: 17 | B22: Jen2x Crossing Catmon | D22: 46204 | E22: Rice (25 kg/sack) | F22: 1 | G22: 1350 | H22: =F22*G22 -> 1350 | I22: =SUMIF(Payments!$B$6:$B$305,$A22,Payments!$D$6:$D$305) -> 0 | J22: =H22-I22 -> 1350 | K22: =IF($H22=0,"",IF(ROUND($J22,2)<0,"OVERPAID",IF(ROUND($J22,2)=0,"PAID",IF($I22>0,"PARTIAL","UNPAID")))) -> UNPAID | L22: =IF(SUMPRODUCT(MAX((Payments!$B$6:$B$305=$A22)*Payments!$A$6:$A$305))=0,"",SUMPRODUCT(MAX((Payments!$B$6:$B$305=$A22)*Payments!$A$6:$A$305)))
A23: 18 | B23: Tita Janeth | D23: 46203 | E23: Rice (25 kg/sack) | F23: 1 | G23: 1200 | H23: =F23*G23 -> 1200 | I23: =SUMIF(Payments!$B$6:$B$305,$A23,Payments!$D$6:$D$305) -> 0 | J23: =H23-I23 -> 1200 | K23: =IF($H23=0,"",IF(ROUND($J23,2)<0,"OVERPAID",IF(ROUND($J23,2)=0,"PAID",IF($I23>0,"PARTIAL","UNPAID")))) -> UNPAID | L23: =IF(SUMPRODUCT(MAX((Payments!$B$6:$B$305=$A23)*Payments!$A$6:$A$305))=0,"",SUMPRODUCT(MAX((Payments!$B$6:$B$305=$A23)*Payments!$A$6:$A$305)))
A24: 19 | B24: Julius | D24: 46207 | E24: Rice (25 kg/sack) | F24: 1 | G24: 1400 | H24: =F24*G24 -> 1400 | I24: =SUMIF(Payments!$B$6:$B$305,$A24,Payments!$D$6:$D$305) -> 0 | J24: =H24-I24 -> 1400 | K24: =IF($H24=0,"",IF(ROUND($J24,2)<0,"OVERPAID",IF(ROUND($J24,2)=0,"PAID",IF($I24>0,"PARTIAL","UNPAID")))) -> UNPAID | L24: =IF(SUMPRODUCT(MAX((Payments!$B$6:$B$305=$A24)*Payments!$A$6:$A$305))=0,"",SUMPRODUCT(MAX((Payments!$B$6:$B$305=$A24)*Payments!$A$6:$A$305)))
A25: 20 | B25: Anghel | D25: 46207 | E25: Rice (25 kg/sack) | F25: 1 | G25: 1400 | H25: =F25*G25 -> 1400 | I25: =SUMIF(Payments!$B$6:$B$305,$A25,Payments!$D$6:$D$305) -> 0 | J25: =H25-I25 -> 1400 | K25: =IF($H25=0,"",IF(ROUND($J25,2)<0,"OVERPAID",IF(ROUND($J25,2)=0,"PAID",IF($I25>0,"PARTIAL","UNPAID")))) -> UNPAID | L25: =IF(SUMPRODUCT(MAX((Payments!$B$6:$B$305=$A25)*Payments!$A$6:$A$305))=0,"",SUMPRODUCT(MAX((Payments!$B$6:$B$305=$A25)*Payments!$A$6:$A$305))) | M25: Highlighted red in the source ledger — meaning to be confirmed.
A26: 21 | B26: Atan Verano | D26: 46209 | E26: Rice (50 kg/sack) | F26: 1 | G26: 2500 | H26: =F26*G26 -> 2500 | I26: =SUMIF(Payments!$B$6:$B$305,$A26,Payments!$D$6:$D$305) -> 0 | J26: =H26-I26 -> 2500 | K26: =IF($H26=0,"",IF(ROUND($J26,2)<0,"OVERPAID",IF(ROUND($J26,2)=0,"PAID",IF($I26>0,"PARTIAL","UNPAID")))) -> UNPAID | L26: =IF(SUMPRODUCT(MAX((Payments!$B$6:$B$305=$A26)*Payments!$A$6:$A$305))=0,"",SUMPRODUCT(MAX((Payments!$B$6:$B$305=$A26)*Payments!$A$6:$A$305))) | M26: Highlighted red in the source ledger — meaning to be confirmed.
A27: 22 | B27: Romel Sode | D27: 46209 | E27: Rice (25 kg/sack) | F27: 1 | G27: 1400 | H27: =F27*G27 -> 1400 | I27: =SUMIF(Payments!$B$6:$B$305,$A27,Payments!$D$6:$D$305) -> 0 | J27: =H27-I27 -> 1400 | K27: =IF($H27=0,"",IF(ROUND($J27,2)<0,"OVERPAID",IF(ROUND($J27,2)=0,"PAID",IF($I27>0,"PARTIAL","UNPAID")))) -> UNPAID | L27: =IF(SUMPRODUCT(MAX((Payments!$B$6:$B$305=$A27)*Payments!$A$6:$A$305))=0,"",SUMPRODUCT(MAX((Payments!$B$6:$B$305=$A27)*Payments!$A$6:$A$305))) | M27: Highlighted red in the source ledger — meaning to be confirmed.
A28: 23 | B28: Victor | D28: 46209 | E28: Rice (25 kg/sack) | F28: 1 | G28: 1400 | H28: =F28*G28 -> 1400 | I28: =SUMIF(Payments!$B$6:$B$305,$A28,Payments!$D$6:$D$305) -> 0 | J28: =H28-I28 -> 1400 | K28: =IF($H28=0,"",IF(ROUND($J28,2)<0,"OVERPAID",IF(ROUND($J28,2)=0,"PAID",IF($I28>0,"PARTIAL","UNPAID")))) -> UNPAID | L28: =IF(SUMPRODUCT(MAX((Payments!$B$6:$B$305=$A28)*Payments!$A$6:$A$305))=0,"",SUMPRODUCT(MAX((Payments!$B$6:$B$305=$A28)*Payments!$A$6:$A$305))) | M28: Highlighted grey in the source ledger — meaning to be confirmed.
A29: 24 | B29: Leni | D29: 46209 | E29: Rice (25 kg/sack) | F29: 1 | G29: 1400 | H29: =F29*G29 -> 1400 | I29: =SUMIF(Payments!$B$6:$B$305,$A29,Payments!$D$6:$D$305) -> 0 | J29: =H29-I29 -> 1400 | K29: =IF($H29=0,"",IF(ROUND($J29,2)<0,"OVERPAID",IF(ROUND($J29,2)=0,"PAID",IF($I29>0,"PARTIAL","UNPAID")))) -> UNPAID | L29: =IF(SUMPRODUCT(MAX((Payments!$B$6:$B$305=$A29)*Payments!$A$6:$A$305))=0,"",SUMPRODUCT(MAX((Payments!$B$6:$B$305=$A29)*Payments!$A$6:$A$305)))
A30: 25 | B30: Gulayan Nanay | D30: 46210 | E30: Rice (50 kg/sack) | F30: 5 | G30: 2600 | H30: =F30*G30 -> 13000 | I30: =SUMIF(Payments!$B$6:$B$305,$A30,Payments!$D$6:$D$305) -> 0 | J30: =H30-I30 -> 13000 | K30: =IF($H30=0,"",IF(ROUND($J30,2)<0,"OVERPAID",IF(ROUND($J30,2)=0,"PAID",IF($I30>0,"PARTIAL","UNPAID")))) -> UNPAID | L30: =IF(SUMPRODUCT(MAX((Payments!$B$6:$B$305=$A30)*Payments!$A$6:$A$305))=0,"",SUMPRODUCT(MAX((Payments!$B$6:$B$305=$A30)*Payments!$A$6:$A$305)))
A31: 26 | B31: Papa | D31: 46214 | E31: Rice (25 kg/sack) | F31: 1 | G31: 1200 | H31: =F31*G31 -> 1200 | I31: =SUMIF(Payments!$B$6:$B$305,$A31,Payments!$D$6:$D$305) -> 0 | J31: =H31-I31 -> 1200 | K31: =IF($H31=0,"",IF(ROUND($J31,2)<0,"OVERPAID",IF(ROUND($J31,2)=0,"PAID",IF($I31>0,"PARTIAL","UNPAID")))) -> UNPAID | L31: =IF(SUMPRODUCT(MAX((Payments!$B$6:$B$305=$A31)*Payments!$A$6:$A$305))=0,"",SUMPRODUCT(MAX((Payments!$B$6:$B$305=$A31)*Payments!$A$6:$A$305)))
A32: 27 | B32: Jun2x SM | D32: 46215 | E32: Rice (25 kg/sack) | F32: 1 | G32: 1400 | H32: =F32*G32 -> 1400 | I32: =SUMIF(Payments!$B$6:$B$305,$A32,Payments!$D$6:$D$305) -> 0 | J32: =H32-I32 -> 1400 | K32: =IF($H32=0,"",IF(ROUND($J32,2)<0,"OVERPAID",IF(ROUND($J32,2)=0,"PAID",IF($I32>0,"PARTIAL","UNPAID")))) -> UNPAID | L32: =IF(SUMPRODUCT(MAX((Payments!$B$6:$B$305=$A32)*Payments!$A$6:$A$305))=0,"",SUMPRODUCT(MAX((Payments!$B$6:$B$305=$A32)*Payments!$A$6:$A$305)))
A33: 28 | B33: Kadok | D33: 46215 | E33: Rice (25 kg/sack) | F33: 1 | G33: 1400 | H33: =F33*G33 -> 1400 | I33: =SUMIF(Payments!$B$6:$B$305,$A33,Payments!$D$6:$D$305) -> 0 | J33: =H33-I33 -> 1400 | K33: =IF($H33=0,"",IF(ROUND($J33,2)<0,"OVERPAID",IF(ROUND($J33,2)=0,"PAID",IF($I33>0,"PARTIAL","UNPAID")))) -> UNPAID | L33: =IF(SUMPRODUCT(MAX((Payments!$B$6:$B$305=$A33)*Payments!$A$6:$A$305))=0,"",SUMPRODUCT(MAX((Payments!$B$6:$B$305=$A33)*Payments!$A$6:$A$305))) | M33: Highlighted red in the source ledger — meaning to be confirmed.
A34: 29 | B34: Jun2x B | D34: 46245 | E34: Rice (25 kg/sack) | F34: 1 | G34: 1450 | H34: =F34*G34 -> 1450 | I34: =SUMIF(Payments!$B$6:$B$305,$A34,Payments!$D$6:$D$305) -> 0 | J34: =H34-I34 -> 1450 | K34: =IF($H34=0,"",IF(ROUND($J34,2)<0,"OVERPAID",IF(ROUND($J34,2)=0,"PAID",IF($I34>0,"PARTIAL","UNPAID")))) -> UNPAID | L34: =IF(SUMPRODUCT(MAX((Payments!$B$6:$B$305=$A34)*Payments!$A$6:$A$305))=0,"",SUMPRODUCT(MAX((Payments!$B$6:$B$305=$A34)*Payments!$A$6:$A$305)))
A35: 30 | B35: Bryan | D35: 46215 | E35: Rice (25 kg/sack) | F35: 1 | G35: 1450 | H35: =F35*G35 -> 1450 | I35: =SUMIF(Payments!$B$6:$B$305,$A35,Payments!$D$6:$D$305) -> 0 | J35: =H35-I35 -> 1450 | K35: =IF($H35=0,"",IF(ROUND($J35,2)<0,"OVERPAID",IF(ROUND($J35,2)=0,"PAID",IF($I35>0,"PARTIAL","UNPAID")))) -> UNPAID | L35: =IF(SUMPRODUCT(MAX((Payments!$B$6:$B$305=$A35)*Payments!$A$6:$A$305))=0,"",SUMPRODUCT(MAX((Payments!$B$6:$B$305=$A35)*Payments!$A$6:$A$305)))
A36: 31 | B36: Jun2x SM | D36: 46237 | E36: Rice (25 kg/sack) | F36: 1 | G36: 1450 | H36: =F36*G36 -> 1450 | I36: =SUMIF(Payments!$B$6:$B$305,$A36,Payments!$D$6:$D$305) -> 0 | J36: =H36-I36 -> 1450 | K36: =IF($H36=0,"",IF(ROUND($J36,2)<0,"OVERPAID",IF(ROUND($J36,2)=0,"PAID",IF($I36>0,"PARTIAL","UNPAID")))) -> UNPAID | L36: =IF(SUMPRODUCT(MAX((Payments!$B$6:$B$305=$A36)*Payments!$A$6:$A$305))=0,"",SUMPRODUCT(MAX((Payments!$B$6:$B$305=$A36)*Payments!$A$6:$A$305)))
A37: 32 | B37: Gulayan Nanay 2 | D37: 46237 | E37: Rice (25 kg/sack) | F37: 10 | G37: 1300 | H37: =F37*G37 -> 13000 | I37: =SUMIF(Payments!$B$6:$B$305,$A37,Payments!$D$6:$D$305) -> 0 | J37: =H37-I37 -> 13000 | K37: =IF($H37=0,"",IF(ROUND($J37,2)<0,"OVERPAID",IF(ROUND($J37,2)=0,"PAID",IF($I37>0,"PARTIAL","UNPAID")))) -> UNPAID | L37: =IF(SUMPRODUCT(MAX((Payments!$B$6:$B$305=$A37)*Payments!$A$6:$A$305))=0,"",SUMPRODUCT(MAX((Payments!$B$6:$B$305=$A37)*Payments!$A$6:$A$305)))
A38: 33 | B38: Julius | D38: 46238 | E38: Rice (25 kg/sack) | F38: 1 | G38: 1450 | H38: =F38*G38 -> 1450 | I38: =SUMIF(Payments!$B$6:$B$305,$A38,Payments!$D$6:$D$305) -> 0 | J38: =H38-I38 -> 1450 | K38: =IF($H38=0,"",IF(ROUND($J38,2)<0,"OVERPAID",IF(ROUND($J38,2)=0,"PAID",IF($I38>0,"PARTIAL","UNPAID")))) -> UNPAID | L38: =IF(SUMPRODUCT(MAX((Payments!$B$6:$B$305=$A38)*Payments!$A$6:$A$305))=0,"",SUMPRODUCT(MAX((Payments!$B$6:$B$305=$A38)*Payments!$A$6:$A$305)))
A39: 34 | B39: Te lenie | D39: 46239 | E39: Rice (25 kg/sack) | F39: 2 | G39: 1450 | H39: =F39*G39 -> 2900 | I39: =SUMIF(Payments!$B$6:$B$305,$A39,Payments!$D$6:$D$305) -> 0 | J39: =H39-I39 -> 2900 | K39: =IF($H39=0,"",IF(ROUND($J39,2)<0,"OVERPAID",IF(ROUND($J39,2)=0,"PAID",IF($I39>0,"PARTIAL","UNPAID")))) -> UNPAID | L39: =IF(SUMPRODUCT(MAX((Payments!$B$6:$B$305=$A39)*Payments!$A$6:$A$305))=0,"",SUMPRODUCT(MAX((Payments!$B$6:$B$305=$A39)*Payments!$A$6:$A$305)))
A40: 35 | B40: Romil | D40: 46239 | E40: Rice (25 kg/sack) | F40: 1 | G40: 1450 | H40: =F40*G40 -> 1450 | I40: =SUMIF(Payments!$B$6:$B$305,$A40,Payments!$D$6:$D$305) -> 0 | J40: =H40-I40 -> 1450 | K40: =IF($H40=0,"",IF(ROUND($J40,2)<0,"OVERPAID",IF(ROUND($J40,2)=0,"PAID",IF($I40>0,"PARTIAL","UNPAID")))) -> UNPAID | L40: =IF(SUMPRODUCT(MAX((Payments!$B$6:$B$305=$A40)*Payments!$A$6:$A$305))=0,"",SUMPRODUCT(MAX((Payments!$B$6:$B$305=$A40)*Payments!$A$6:$A$305)))
A41: 36 | B41: Gulayan Nanay 2 | D41: 46245 | E41: Rice (25 kg/sack) | F41: 10 | G41: 1300 | H41: =F41*G41 -> 13000 | I41: =SUMIF(Payments!$B$6:$B$305,$A41,Payments!$D$6:$D$305) -> 0 | J41: =H41-I41 -> 13000 | K41: =IF($H41=0,"",IF(ROUND($J41,2)<0,"OVERPAID",IF(ROUND($J41,2)=0,"PAID",IF($I41>0,"PARTIAL","UNPAID")))) -> UNPAID | L41: =IF(SUMPRODUCT(MAX((Payments!$B$6:$B$305=$A41)*Payments!$A$6:$A$305))=0,"",SUMPRODUCT(MAX((Payments!$B$6:$B$305=$A41)*Payments!$A$6:$A$305))) | M41: Same customer, qty and amount as an earlier row — confirm it is not a duplicate entry.
...

Sheet Payments
A1: PAYMENTS RECEIVED
A2: One row per payment. A customer may pay in as many instalments as they like — just add another row.
A3: FILL IN THE YELLOW COLUMNS ONLY: Payment Date, Ledger ID, Amount Paid, Method, Notes. The Customer column fills itself from the Ledger ID, and the ledger updates automatically.
A5: Payment Date | B5: Ledger ID | C5: Customer (auto) | D5: Amount Paid (PHP) | E5: Method | F5: Notes | H5: EXAMPLE — reference only, nothing here is counted
C6: =IF($B6="","",IFERROR(INDEX('Credit Ledger'!$B$6:$B$45,MATCH($B6,'Credit Ledger'!$A$6:$A$45,0)),"** ID not found **")) | H6: Payment Date | I6: Ledger ID | J6: Customer (auto) | K6: Amount Paid (PHP) | L6: Method | M6: Notes
C7: =IF($B7="","",IFERROR(INDEX('Credit Ledger'!$B$6:$B$45,MATCH($B7,'Credit Ledger'!$A$6:$A$45,0)),"** ID not found **")) | H7: 46264 | I7: 20 | J7: Anghel | K7: 700 | L7: CASH | M7: part payment, balance 700.00
C8: =IF($B8="","",IFERROR(INDEX('Credit Ledger'!$B$6:$B$45,MATCH($B8,'Credit Ledger'!$A$6:$A$45,0)),"** ID not found **"))
C9: =IF($B9="","",IFERROR(INDEX('Credit Ledger'!$B$6:$B$45,MATCH($B9,'Credit Ledger'!$A$6:$A$45,0)),"** ID not found **")) | H9: Anghel's 04 Jul sale is Ledger ID 20 for 1,400.00. Typing that row on the left makes the ledger show Total Paid 700.00, Balance 700.00, Status PARTIAL. Pay the rest later and it turns PAID.
C10: =IF($B10="","",IFERROR(INDEX('Credit Ledger'!$B$6:$B$45,MATCH($B10,'Credit Ledger'!$A$6:$A$45,0)),"** ID not found **"))
C11: =IF($B11="","",IFERROR(INDEX('Credit Ledger'!$B$6:$B$45,MATCH($B11,'Credit Ledger'!$A$6:$A$45,0)),"** ID not found **"))
C12: =IF($B12="","",IFERROR(INDEX('Credit Ledger'!$B$6:$B$45,MATCH($B12,'Credit Ledger'!$A$6:$A$45,0)),"** ID not found **"))
C13: =IF($B13="","",IFERROR(INDEX('Credit Ledger'!$B$6:$B$45,MATCH($B13,'Credit Ledger'!$A$6:$A$45,0)),"** ID not found **"))
C14: =IF($B14="","",IFERROR(INDEX('Credit Ledger'!$B$6:$B$45,MATCH($B14,'Credit Ledger'!$A$6:$A$45,0)),"** ID not found **"))
C15: =IF($B15="","",IFERROR(INDEX('Credit Ledger'!$B$6:$B$45,MATCH($B15,'Credit Ledger'!$A$6:$A$45,0)),"** ID not found **"))
C16: =IF($B16="","",IFERROR(INDEX('Credit Ledger'!$B$6:$B$45,MATCH($B16,'Credit Ledger'!$A$6:$A$45,0)),"** ID not found **"))
C17: =IF($B17="","",IFERROR(INDEX('Credit Ledger'!$B$6:$B$45,MATCH($B17,'Credit Ledger'!$A$6:$A$45,0)),"** ID not found **"))
C18: =IF($B18="","",IFERROR(INDEX('Credit Ledger'!$B$6:$B$45,MATCH($B18,'Credit Ledger'!$A$6:$A$45,0)),"** ID not found **"))
C19: =IF($B19="","",IFERROR(INDEX('Credit Ledger'!$B$6:$B$45,MATCH($B19,'Credit Ledger'!$A$6:$A$45,0)),"** ID not found **"))
C20: =IF($B20="","",IFERROR(INDEX('Credit Ledger'!$B$6:$B$45,MATCH($B20,'Credit Ledger'!$A$6:$A$45,0)),"** ID not found **"))
C21: =IF($B21="","",IFERROR(INDEX('Credit Ledger'!$B$6:$B$45,MATCH($B21,'Credit Ledger'!$A$6:$A$45,0)),"** ID not found **"))
... C305: =IF($B305="","",IFERROR(INDEX('Credit Ledger'!$B$6:$B$45,MATCH($B305,'Credit Ledger'!$A$6:$A$45,0)),"** ID not found **"))
C307: TOTAL COLLECTED | D307: =SUM(D6:D305) -> 0

Sheet Customer Summary
A1: OUTSTANDING BALANCE BY CUSTOMER
A2: Every figure here is a formula over the Credit Ledger. Nothing to type.
A3: Use this sheet when collecting: it is the running utang of each customer across all their sales.
A5: Customer Name | B5: Sales | C5: Sacks | D5: Total Credit (PHP) | E5: Total Paid (PHP) | F5: Balance Due (PHP) | G5: Status
A6: (name blank in source) | B6: =COUNTIF('Credit Ledger'!$B$6:$B$45,$A6) -> 1 | C6: =SUMIF('Credit Ledger'!$B$6:$B$45,$A6,'Credit Ledger'!$F$6:$F$45) -> 1 | D6: =SUMIF('Credit Ledger'!$B$6:$B$45,$A6,'Credit Ledger'!$H$6:$H$45) -> 1450 | E6: =SUMIF('Credit Ledger'!$B$6:$B$45,$A6,'Credit Ledger'!$I$6:$I$45) -> 0 | F6: =D6-E6 -> 1450 | G6: =IF(ROUND(F6,2)<0,"OVERPAID",IF(ROUND(F6,2)=0,"PAID",IF(E6>0,"PARTIAL","UNPAID"))) -> UNPAID
A7: Anghel | B7: =COUNTIF('Credit Ledger'!$B$6:$B$45,$A7) -> 2 | C7: =SUMIF('Credit Ledger'!$B$6:$B$45,$A7,'Credit Ledger'!$F$6:$F$45) -> 2 | D7: =SUMIF('Credit Ledger'!$B$6:$B$45,$A7,'Credit Ledger'!$H$6:$H$45) -> 2850 | E7: =SUMIF('Credit Ledger'!$B$6:$B$45,$A7,'Credit Ledger'!$I$6:$I$45) -> 0 | F7: =D7-E7 -> 2850 | G7: =IF(ROUND(F7,2)<0,"OVERPAID",IF(ROUND(F7,2)=0,"PAID",IF(E7>0,"PARTIAL","UNPAID"))) -> UNPAID
A8: Atan Verano | B8: =COUNTIF('Credit Ledger'!$B$6:$B$45,$A8) -> 1 | C8: =SUMIF('Credit Ledger'!$B$6:$B$45,$A8,'Credit Ledger'!$F$6:$F$45) -> 1 | D8: =SUMIF('Credit Ledger'!$B$6:$B$45,$A8,'Credit Ledger'!$H$6:$H$45) -> 2500 | E8: =SUMIF('Credit Ledger'!$B$6:$B$45,$A8,'Credit Ledger'!$I$6:$I$45) -> 0 | F8: =D8-E8 -> 2500 | G8: =IF(ROUND(F8,2)<0,"OVERPAID",IF(ROUND(F8,2)=0,"PAID",IF(E8>0,"PARTIAL","UNPAID"))) -> UNPAID
A9: Ate Lenie | B9: =COUNTIF('Credit Ledger'!$B$6:$B$45,$A9) -> 1 | C9: =SUMIF('Credit Ledger'!$B$6:$B$45,$A9,'Credit Ledger'!$F$6:$F$45) -> 1 | D9: =SUMIF('Credit Ledger'!$B$6:$B$45,$A9,'Credit Ledger'!$H$6:$H$45) -> 2800 | E9: =SUMIF('Credit Ledger'!$B$6:$B$45,$A9,'Credit Ledger'!$I$6:$I$45) -> 0 | F9: =D9-E9 -> 2800 | G9: =IF(ROUND(F9,2)<0,"OVERPAID",IF(ROUND(F9,2)=0,"PAID",IF(E9>0,"PARTIAL","UNPAID"))) -> UNPAID
A10: Bryan | B10: =COUNTIF('Credit Ledger'!$B$6:$B$45,$A10) -> 2 | C10: =SUMIF('Credit Ledger'!$B$6:$B$45,$A10,'Credit Ledger'!$F$6:$F$45) -> 2 | D10: =SUMIF('Credit Ledger'!$B$6:$B$45,$A10,'Credit Ledger'!$H$6:$H$45) -> 2850 | E10: =SUMIF('Credit Ledger'!$B$6:$B$45,$A10,'Credit Ledger'!$I$6:$I$45) -> 0 | F10: =D10-E10 -> 2850 | G10: =IF(ROUND(F10,2)<0,"OVERPAID",IF(ROUND(F10,2)=0,"PAID",IF(E10>0,"PARTIAL","UNPAID"))) -> UNPAID
A11: Gulayan Nanay | B11: =COUNTIF('Credit Ledger'!$B$6:$B$45,$A11) -> 1 | C11: =SUMIF('Credit Ledger'!$B$6:$B$45,$A11,'Credit Ledger'!$F$6:$F$45) -> 5 | D11: =SUMIF('Credit Ledger'!$B$6:$B$45,$A11,'Credit Ledger'!$H$6:$H$45) -> 13000 | E11: =SUMIF('Credit Ledger'!$B$6:$B$45,$A11,'Credit Ledger'!$I$6:$I$45) -> 0 | F11: =D11-E11 -> 13000 | G11: =IF(ROUND(F11,2)<0,"OVERPAID",IF(ROUND(F11,2)=0,"PAID",IF(E11>0,"PARTIAL","UNPAID"))) -> UNPAID
A12: Gulayan Nanay 2 | B12: =COUNTIF('Credit Ledger'!$B$6:$B$45,$A12) -> 2 | C12: =SUMIF('Credit Ledger'!$B$6:$B$45,$A12,'Credit Ledger'!$F$6:$F$45) -> 20 | D12: =SUMIF('Credit Ledger'!$B$6:$B$45,$A12,'Credit Ledger'!$H$6:$H$45) -> 26000 | E12: =SUMIF('Credit Ledger'!$B$6:$B$45,$A12,'Credit Ledger'!$I$6:$I$45) -> 0 | F12: =D12-E12 -> 26000 | G12: =IF(ROUND(F12,2)<0,"OVERPAID",IF(ROUND(F12,2)=0,"PAID",IF(E12>0,"PARTIAL","UNPAID"))) -> UNPAID
A13: Jen2x Crossing Catmon | B13: =COUNTIF('Credit Ledger'!$B$6:$B$45,$A13) -> 1 | C13: =SUMIF('Credit Ledger'!$B$6:$B$45,$A13,'Credit Ledger'!$F$6:$F$45) -> 1 | D13: =SUMIF('Credit Ledger'!$B$6:$B$45,$A13,'Credit Ledger'!$H$6:$H$45) -> 1350 | E13: =SUMIF('Credit Ledger'!$B$6:$B$45,$A13,'Credit Ledger'!$I$6:$I$45) -> 0 | F13: =D13-E13 -> 1350 | G13: =IF(ROUND(F13,2)<0,"OVERPAID",IF(ROUND(F13,2)=0,"PAID",IF(E13>0,"PARTIAL","UNPAID"))) -> UNPAID
A14: JR | B14: =COUNTIF('Credit Ledger'!$B$6:$B$45,$A14) -> 1 | C14: =SUMIF('Credit Ledger'!$B$6:$B$45,$A14,'Credit Ledger'!$F$6:$F$45) -> 1 | D14: =SUMIF('Credit Ledger'!$B$6:$B$45,$A14,'Credit Ledger'!$H$6:$H$45) -> 1400 | E14: =SUMIF('Credit Ledger'!$B$6:$B$45,$A14,'Credit Ledger'!$I$6:$I$45) -> 0 | F14: =D14-E14 -> 1400 | G14: =IF(ROUND(F14,2)<0,"OVERPAID",IF(ROUND(F14,2)=0,"PAID",IF(E14>0,"PARTIAL","UNPAID"))) -> UNPAID
A15: Juaton Crossing | B15: =COUNTIF('Credit Ledger'!$B$6:$B$45,$A15) -> 2 | C15: =SUMIF('Credit Ledger'!$B$6:$B$45,$A15,'Credit Ledger'!$F$6:$F$45) -> 4 | D15: =SUMIF('Credit Ledger'!$B$6:$B$45,$A15,'Credit Ledger'!$H$6:$H$45) -> 8400 | E15: =SUMIF('Credit Ledger'!$B$6:$B$45,$A15,'Credit Ledger'!$I$6:$I$45) -> 0 | F15: =D15-E15 -> 8400 | G15: =IF(ROUND(F15,2)<0,"OVERPAID",IF(ROUND(F15,2)=0,"PAID",IF(E15>0,"PARTIAL","UNPAID"))) -> UNPAID
A16: Julius | B16: =COUNTIF('Credit Ledger'!$B$6:$B$45,$A16) -> 3 | C16: =SUMIF('Credit Ledger'!$B$6:$B$45,$A16,'Credit Ledger'!$F$6:$F$45) -> 3 | D16: =SUMIF('Credit Ledger'!$B$6:$B$45,$A16,'Credit Ledger'!$H$6:$H$45) -> 4250 | E16: =SUMIF('Credit Ledger'!$B$6:$B$45,$A16,'Credit Ledger'!$I$6:$I$45) -> 0 | F16: =D16-E16 -> 4250 | G16: =IF(ROUND(F16,2)<0,"OVERPAID",IF(ROUND(F16,2)=0,"PAID",IF(E16>0,"PARTIAL","UNPAID"))) -> UNPAID
A17: Jun2x B | B17: =COUNTIF('Credit Ledger'!$B$6:$B$45,$A17) -> 2 | C17: =SUMIF('Credit Ledger'!$B$6:$B$45,$A17,'Credit Ledger'!$F$6:$F$45) -> 2 | D17: =SUMIF('Credit Ledger'!$B$6:$B$45,$A17,'Credit Ledger'!$H$6:$H$45) -> 2850 | E17: =SUMIF('Credit Ledger'!$B$6:$B$45,$A17,'Credit Ledger'!$I$6:$I$45) -> 0 | F17: =D17-E17 -> 2850 | G17: =IF(ROUND(F17,2)<0,"OVERPAID",IF(ROUND(F17,2)=0,"PAID",IF(E17>0,"PARTIAL","UNPAID"))) -> UNPAID
... A34: Victor | B34: =COUNTIF('Credit Ledger'!$B$6:$B$45,$A34) -> 1 | C34: =SUMIF('Credit Ledger'!$B$6:$B$45,$A34,'Credit Ledger'!$F$6:$F$45) -> 1 | D34: =SUMIF('Credit Ledger'!$B$6:$B$45,$A34,'Credit Ledger'!$H$6:$H$45) -> 1400 | E34: =SUMIF('Credit Ledger'!$B$6:$B$45,$A34,'Credit Ledger'!$I$6:$I$45) -> 0 | F34: =D34-E34 -> 1400 | G34: =IF(ROUND(F34,2)<0,"OVERPAID",IF(ROUND(F34,2)=0,"PAID",IF(E34>0,"PARTIAL","UNPAID"))) -> UNPAID
A36: TOTAL — 29 customers | B36: =SUM(B6:B34) -> 40 | C36: =SUM(C6:C34) -> 66 | D36: =SUM(D6:D34) -> 106000 | E36: =SUM(E6:E34) -> 0 | F36: =SUM(F6:F34) -> 106000
A38: Note: names are grouped exactly as written in the source ledger. If two spellings are the same person (e.g. 'Ate Lenie' / 'Te lenie'), tell me and I will merge them.

Sheet Excluded (Cash)
A1: ROWS EXCLUDED FROM THE CREDIT LEDGER
A2: These two rows are marked CASH in the source ledger, so they carry no balance and are kept here for the record.
A3: If either one was actually on credit, tell me and I will move it into the Credit Ledger.
A5: Customer Name | B5: Transaction Date | C5: Product Type | D5: Qty (Sacks) | E5: Unit Price (PHP) | F5: Total Amount (PHP) | G5: Payment Method
A6: Nanay Juaton | B6: 46191 | C6: Rice (25 kg/sack) | D6: 2 | E6: 1300 | F6: =D6*E6 -> 2600 | G6: CASH
A7: Catmon Tinadahan | B7: 46193 | C7: Rice (25 kg/sack) | D7: 1 | E7: 1300 | F7: =D7*E7 -> 1300 | G7: CASH
